Workbook

Sheet README
A1: Pharma Valuation Explorer: model workbook
A2: Generated 2026-10-20 from public SEC XBRL data (Forms 20-F) and ECB reference rates.
A4: What this is
A5: A transparent comparison of Novartis, AstraZeneca and GSK for FY2023-FY2025, and a DCF for AstraZeneca. It is an educational model, not investment advice or a price target.
A7: Sheets
A8: Dataset: every figure with its XBRL tag, SEC accession number and filing date. FX: ECB reference rates. Comparables: formulas over Dataset. DCF: inputs in blue, formulas elsewhere. Sensitivity: value per share across WACC and terminal growth. Checks: identity tests.
A10: Key definitions
A11: Revenue: AstraZeneca total revenue; GSK turnover; Novartis net sales plus other revenues. Profit: continuing operations (Novartis 2023 excludes the Sandoz distribution gain).
A12: Debt: financial debt including lease liabilities. Net debt: debt less cash and, for Novartis, marketable securities and time deposits. Free cash flow: operating cash flow less purchases of PP&E (and, in the stricter version, intangible assets).
A13: GSK is reported in GBP; USD translation uses ECB rates (annual average for flows, year-end for balances).
A15: Limits you should know
A16: The DCF bridge is partial: it omits contingent consideration, litigation and other provisions, deferred tax, other investments and any dividends declared. Terminal value is about three quarters of enterprise value in the base case. Scenario assumptions are illustrative, not forecasts.
... A18: The reconciliation to filing pages is a consistency check (137 figures), not an audit.

Sheet Dataset
A1: Company | B1: Year | C1: Metric | D1: Value (millions, reporting currency) | E1: Currency | F1: Source tag | G1: SEC accession | H1: Filing date | I1: Filing index
A2: Novartis | B2: 2023 | C2: revenue | D2: 46660 | E2: USD | F2: RevenueFromSaleOfGoods + OtherRevenue | G2: 0001114448-26-000004 | H2: 2026-02-04 | I2: https://www.sec.gov/Archives/edgar/data/1114448/000111444826000004/
A3: Novartis | B3: 2023 | C3: operating_profit | D3: 9769 | E3: USD | F3: ProfitLossFromOperatingActivities | G3: 0001114448-26-000004 | H3: 2026-02-04 | I3: https://www.sec.gov/Archives/edgar/data/1114448/000111444826000004/
A4: Novartis | B4: 2023 | C4: pretax_profit | D4: 9123 | E4: USD | F4: ProfitLossBeforeTax | G4: 0001114448-26-000004 | H4: 2026-02-04 | I4: https://www.sec.gov/Archives/edgar/data/1114448/000111444826000004/
A5: Novartis | B5: 2023 | C5: income_tax | D5: 551 | E5: USD | F5: IncomeTaxExpenseContinuingOperations | G5: 0001114448-26-000004 | H5: 2026-02-04 | I5: https://www.sec.gov/Archives/edgar/data/1114448/000111444826000004/
A6: Novartis | B6: 2023 | C6: profit_continuing | D6: 8572 | E6: USD | F6: ProfitLossFromContinuingOperations | G6: 0001114448-26-000004 | H6: 2026-02-04 | I6: https://www.sec.gov/Archives/edgar/data/1114448/000111444826000004/
A7: Novartis | B7: 2023 | C7: nci_profit | D7: 4 | E7: USD | F7: ProfitLossAttributableToNoncontrollingInterests | G7: 0001114448-26-000004 | H7: 2026-02-04 | I7: https://www.sec.gov/Archives/edgar/data/1114448/000111444826000004/
A8: Novartis | B8: 2023 | C8: rnd | D8: 11371 | E8: USD | F8: ResearchAndDevelopmentExpense | G8: 0001114448-26-000004 | H8: 2026-02-04 | I8: https://www.sec.gov/Archives/edgar/data/1114448/000111444826000004/
A9: Novartis | B9: 2023 | C9: cfo | D9: 14220 | E9: USD | F9: CashFlowsFromUsedInOperatingActivitiesContinuingOperations | G9: 0001114448-26-000004 | H9: 2026-02-04 | I9: https://www.sec.gov/Archives/edgar/data/1114448/000111444826000004/
A10: Novartis | B10: 2023 | C10: capex_ppe | D10: 1060 | E10: USD | F10: PurchaseOfPropertyPlantAndEquipmentClassifiedAsInvestingActivities | G10: 0001114448-26-000004 | H10: 2026-02-04 | I10: https://www.sec.gov/Archives/edgar/data/1114448/000111444826000004/
A11: Novartis | B11: 2023 | C11: capex_intangibles | D11: 1693 | E11: USD | F11: PurchaseOfIntangibleAssetsClassifiedAsInvestingActivities | G11: 0001114448-26-000004 | H11: 2026-02-04 | I11: https://www.sec.gov/Archives/edgar/data/1114448/000111444826000004/
A12: Novartis | B12: 2023 | C12: cash | D12: 13393 | E12: USD | F12: CashAndCashEquivalents | G12: 0001114448-26-000004 | H12: 2026-02-04 | I12: https://www.sec.gov/Archives/edgar/data/1114448/000111444826000004/
A13: Novartis | B13: 2023 | C13: liquid_investments | D13: 1035 | E13: USD | F13: OtherCurrentFinancialAssets | G13: 0001370368-25-000004 | H13: 2025-01-31 | I13: https://www.sec.gov/Archives/edgar/data/1114448/000137036825000004/
... A72: AstraZeneca | B72: 2023 | C72: equity_method_investments | D72: 147 | E72: USD | F72: InvestmentAccountedForUsingEquityMethod | G72: 0001104659-26-019130 | H72: 2026-02-24 | I72: https://www.sec.gov/Archives/edgar/data/901832/000110465926019130/
A73: AstraZeneca | B73: 2023 | C73: debt_financial | D73: 27494 | E73: USD | F73: derived
A74: AstraZeneca | B74: 2023 | C74: shares_outstanding_m | D74: 1552 | E74: USD | F74: IssuedCapital / 0.25 nominal | G74: 0001104659-25-014750 | H74: 2025-02-18 | I74: https://www.sec.gov/Archives/edgar/data/901832/000110465925014750/
A75: AstraZeneca | B75: 2024 | C75: revenue | D75: 54073 | E75: USD | F75: Revenue | G75: 0001104659-26-019130 | H75: 2026-02-24 | I75: https://www.sec.gov/Archives/edgar/data/901832/000110465926019130/
A76: AstraZeneca | B76: 2024 | C76: operating_profit | D76: 10003 | E76: USD | F76: ProfitLossFromOperatingActivities | G76: 0001104659-26-019130 | H76: 2026-02-24 | I76: https://www.sec.gov/Archives/edgar/data/901832/000110465926019130/
A77: AstraZeneca | B77: 2024 | C77: pretax_profit | D77: 8691 | E77: USD | F77: ProfitLossBeforeTax | G77: 0001104659-26-019130 | H77: 2026-02-24 | I77: https://www.sec.gov/Archives/edgar/data/901832/000110465926019130/
A78: AstraZeneca | B78: 2024 | C78: income_tax | D78: 1650 | E78: USD | F78: IncomeTaxExpenseContinuingOperations | G78: 0001104659-26-019130 | H78: 2026-02-24 | I78: https://www.sec.gov/Archives/edgar/data/901832/000110465926019130/
A79: AstraZeneca | B79: 2024 | C79: profit_continuing | D79: 7041 | E79: USD | F79: ProfitLoss | G79: 0001104659-26-019130 | H79: 2026-02-24 | I79: https://www.sec.gov/Archives/edgar/data/901832/000110465926019130/
A80: AstraZeneca | B80: 2024 | C80: nci_profit | D80: 6 | E80: USD | F80: ProfitLossAttributableToNoncontrollingInterests | G80: 0001104659-26-019130 | H80: 2026-02-24 | I80: https://www.sec.gov/Archives/edgar/data/901832/000110465926019130/
A81: AstraZeneca | B81: 2024 | C81: rnd | D81: 13583 | E81: USD | F81: ResearchAndDevelopmentExpense | G81: 0001104659-26-019130 | H81: 2026-02-24 | I81: https://www.sec.gov/Archives/edgar/data/901832/000110465926019130/
A82: AstraZeneca | B82: 2024 | C82: cfo | D82: 11861 | E82: USD | F82: CashFlowsFromUsedInOperatingActivities | G82: 0001104659-26-019130 | H82: 2026-02-24 | I82: https://www.sec.gov/Archives/edgar/data/901832/000110465926019130/
A83: AstraZeneca | B83: 2024 | C83: capex_ppe | D83: 1924 | E83: USD | F83: PurchaseOfPropertyPlantAndEquipmentClassifiedAsInvestingActivities | G83: 0001104659-26-019130 | H83: 2026-02-24 | I83: https://www.sec.gov/Archives/edgar/data/901832/000110465926019130/
A84: AstraZeneca | B84: 2024 | C84: capex_intangibles | D84: 2662 | E84: USD | F84: PurchaseOfIntangibleAssetsClassifiedAsInvestingActivities | G84: 0001104659-26-019130 | H84: 2026-02-24 | I84: https://www.sec.gov/Archives/edgar/data/901832/000110465926019130/
A85: AstraZeneca | B85: 2024 | C85: cash | D85: 5488 | E85: USD | F85: CashAndCashEquivalents | G85: 0001104659-26-019130 | H85: 2026-02-24 | I85: https://www.sec.gov/Archives/edgar/data/901832/000110465926019130/
... A94: AstraZeneca | B94: 2024 | C94: equity_method_investments | D94: 268 | E94: USD | F94: InvestmentAccountedForUsingEquityMethod | G94: 0001104659-26-019130 | H94: 2026-02-24 | I94: https://www.sec.gov/Archives/edgar/data/901832/000110465926019130/
A95: AstraZeneca | B95: 2024 | C95: debt_financial | D95: 28843 | E95: USD | F95: derived
A96: AstraZeneca | B96: 2024 | C96: shares_outstanding_m | D96: 1552 | E96: USD | F96: IssuedCapital / 0.25 nominal | G96: 0001104659-26-019130 | H96: 2026-02-24 | I96: https://www.sec.gov/Archives/edgar/data/901832/000110465926019130/
A97: AstraZeneca | B97: 2025 | C97: revenue | D97: 58739 | E97: USD | F97: Revenue | G97: 0001104659-26-019130 | H97: 2026-02-24 | I97: https://www.sec.gov/Archives/edgar/data/901832/000110465926019130/
A98: AstraZeneca | B98: 2025 | C98: operating_profit | D98: 13743 | E98: USD | F98: ProfitLossFromOperatingActivities | G98: 0001104659-26-019130 | H98: 2026-02-24 | I98: https://www.sec.gov/Archives/edgar/data/901832/000110465926019130/
A99: AstraZeneca | B99: 2025 | C99: pretax_profit | D99: 12402 | E99: USD | F99: ProfitLossBeforeTax | G99: 0001104659-26-019130 | H99: 2026-02-24 | I99: https://www.sec.gov/Archives/edgar/data/901832/000110465926019130/
A100: AstraZeneca | B100: 2025 | C100: income_tax | D100: 2169 | E100: USD | F100: IncomeTaxExpenseContinuingOperations | G100: 0001104659-26-019130 | H100: 2026-02-24 | I100: https://www.sec.gov/Archives/edgar/data/901832/000110465926019130/
A101: AstraZeneca | B101: 2025 | C101: profit_continuing | D101: 10233 | E101: USD | F101: ProfitLoss | G101: 0001104659-26-019130 | H101: 2026-02-24 | I101: https://www.sec.gov/Archives/edgar/data/901832/000110465926019130/
A102: AstraZeneca | B102: 2025 | C102: nci_profit | D102: 8 | E102: USD | F102: ProfitLossAttributableToNoncontrollingInterests | G102: 0001104659-26-019130 | H102: 2026-02-24 | I102: https://www.sec.gov/Archives/edgar/data/901832/000110465926019130/
A103: AstraZeneca | B103: 2025 | C103: rnd | D103: 14232 | E103: USD | F103: ResearchAndDevelopmentExpense | G103: 0001104659-26-019130 | H103: 2026-02-24 | I103: https://www.sec.gov/Archives/edgar/data/901832/000110465926019130/
A104: AstraZeneca | B104: 2025 | C104: cfo | D104: 14575 | E104: USD | F104: CashFlowsFromUsedInOperatingActivities | G104: 0001104659-26-019130 | H104: 2026-02-24 | I104: https://www.sec.gov/Archives/edgar/data/901832/000110465926019130/
A105: AstraZeneca | B105: 2025 | C105: capex_ppe | D105: 2810 | E105: USD | F105: PurchaseOfPropertyPlantAndEquipmentClassifiedAsInvestingActivities | G105: 0001104659-26-019130 | H105: 2026-02-24 | I105: https://www.sec.gov/Archives/edgar/data/901832/000110465926019130/
A106: AstraZeneca | B106: 2025 | C106: capex_intangibles | D106: 3095 | E106: USD | F106: PurchaseOfIntangibleAssetsClassifiedAsInvestingActivities | G106: 0001104659-26-019130 | H106: 2026-02-24 | I106: https://www.sec.gov/Archives/edgar/data/901832/000110465926019130/
...

Sheet FX
A1: Year | B1: USD per EUR (average) | C1: USD per EUR (year-end) | D1: GBP per EUR (average) | E1: GBP per EUR (year-end) | F1: USD per GBP (average) | G1: USD per GBP (year-end) | H1: Source
A2: 2023 | B2: 1.0812686 | C2: 1.105 | D2: 0.86978651 | E2: 0.86905 | F2: =B2/D2 -> 1.2431426 | G2: =C2/E2 -> 1.2715034 | H2: European Central Bank euro foreign exchange reference rates (data-api.ecb.europa.eu, dataset EXR)
A3: 2024 | B3: 1.0823805 | C3: 1.0389 | D3: 0.8466166 | E3: 0.82918 | F3: =B3/D3 -> 1.2784777 | G3: =C3/E3 -> 1.2529246
A4: 2025 | B4: 1.1299831 | C4: 1.175 | D4: 0.85679231 | E4: 0.8726 | F4: =B4/D4 -> 1.318853 | G4: =C4/E4 -> 1.3465505

Sheet Comparables
A1: Company | B1: Year | C1: Currency | D1: Revenue | E1: Operating profit | F1: Operating margin | G1: Profit (continuing) | H1: Profit margin | I1: R&D | J1: R&D % revenue | K1: Operating cash flow | L1: Purchases of PP&E | M1: Purchases of intangibles | N1: FCF (CFO - PP&E) | O1: FCF after intangibles | P1: Cash | Q1: Debt incl. leases | R1: Net debt | S1: Revenue (USD m) | T1: FCF after intangibles (USD m)
A2: Novartis | B2: 2023 | C2: USD | D2: =SUMIFS(Dataset!$D:$D,Dataset!$A:$A,$A2,Dataset!$B:$B,$B2,Dataset!$C:$C,"revenue") -> 46660 | E2: =SUMIFS(Dataset!$D:$D,Dataset!$A:$A,$A2,Dataset!$B:$B,$B2,Dataset!$C:$C,"operating_profit") -> 9769 | F2: =E2/D2 -> 0.20936562 | G2: =SUMIFS(Dataset!$D:$D,Dataset!$A:$A,$A2,Dataset!$B:$B,$B2,Dataset!$C:$C,"profit_continuing") -> 8572 | H2: =G2/D2 -> 0.18371196 | I2: =SUMIFS(Dataset!$D:$D,Dataset!$A:$A,$A2,Dataset!$B:$B,$B2,Dataset!$C:$C,"rnd") -> 11371 | J2: =I2/D2 -> 0.2436991 | K2: =SUMIFS(Dataset!$D:$D,Dataset!$A:$A,$A2,Dataset!$B:$B,$B2,Dataset!$C:$C,"cfo") -> 14220 | L2: =SUMIFS(Dataset!$D:$D,Dataset!$A:$A,$A2,Dataset!$B:$B,$B2,Dataset!$C:$C,"capex_ppe") -> 1060 | M2: =SUMIFS(Dataset!$D:$D,Dataset!$A:$A,$A2,Dataset!$B:$B,$B2,Dataset!$C:$C,"capex_intangibles") -> 1693 | N2: =K2-L2 -> 13160 | O2: =K2-L2-M2 -> 11467 | P2: =SUMIFS(Dataset!$D:$D,Dataset!$A:$A,$A2,Dataset!$B:$B,$B2,Dataset!$C:$C,"cash") -> 13393 | Q2: =IF(SUMIFS(Dataset!$D:$D,Dataset!$A:$A,$A2,Dataset!$B:$B,$B2,Dataset!$C:$C,"borrowings_incl_leases")<>0,SUMIFS(Dataset!$D:$D,Dataset!$A:$A,$A2,Dataset!$B:$B,$B2,Dataset!$C:$C,"borrowings_incl_leases"),SUMIFS(Dataset!$D:$D,Dataset!$A:$A,$A2,Dataset!$B:$B,$B2,Dataset!$C:$C,"debt_financial")+SUMIFS(Dataset!$D:$D,Dataset!$A:$A,$A2,Dataset!$B:$B,$B2,Dataset!$C:$C,"lease_liabilities")) -> 26439 | R2: =Q2-P2-SUMIFS(Dataset!$D:$D,Dataset!$A:$A,$A2,Dataset!$B:$B,$B2,Dataset!$C:$C,"liquid_investments") -> 12011 | S2: =D2*IF(C2="GBP",INDEX(FX!$F$2:$F$4,MATCH(B2,FX!$A$2:$A$4,0)),1) -> 46660 | T2: =O2*IF(C2="GBP",INDEX(FX!$F$2:$F$4,MATCH(B2,FX!$A$2:$A$4,0)),1) -> 11467
A3: Novartis | B3: 2024 | C3: USD | D3: =SUMIFS(Dataset!$D:$D,Dataset!$A:$A,$A3,Dataset!$B:$B,$B3,Dataset!$C:$C,"revenue") -> 51722 | E3: =SUMIFS(Dataset!$D:$D,Dataset!$A:$A,$A3,Dataset!$B:$B,$B3,Dataset!$C:$C,"operating_profit") -> 14544 | F3: =E3/D3 -> 0.28119562 | G3: =SUMIFS(Dataset!$D:$D,Dataset!$A:$A,$A3,Dataset!$B:$B,$B3,Dataset!$C:$C,"profit_continuing") -> 11939 | H3: =G3/D3 -> 0.23083021 | I3: =SUMIFS(Dataset!$D:$D,Dataset!$A:$A,$A3,Dataset!$B:$B,$B3,Dataset!$C:$C,"rnd") -> 10022 | J3: =I3/D3 -> 0.19376668 | K3: =SUMIFS(Dataset!$D:$D,Dataset!$A:$A,$A3,Dataset!$B:$B,$B3,Dataset!$C:$C,"cfo") -> 17619 | L3: =SUMIFS(Dataset!$D:$D,Dataset!$A:$A,$A3,Dataset!$B:$B,$B3,Dataset!$C:$C,"capex_ppe") -> 1366 | M3: =SUMIFS(Dataset!$D:$D,Dataset!$A:$A,$A3,Dataset!$B:$B,$B3,Dataset!$C:$C,"capex_intangibles") -> 2448 | N3: =K3-L3 -> 16253 | O3: =K3-L3-M3 -> 13805 | P3: =SUMIFS(Dataset!$D:$D,Dataset!$A:$A,$A3,Dataset!$B:$B,$B3,Dataset!$C:$C,"cash") -> 11459 | Q3: =IF(SUMIFS(Dataset!$D:$D,Dataset!$A:$A,$A3,Dataset!$B:$B,$B3,Dataset!$C:$C,"borrowings_incl_leases")<>0,SUMIFS(Dataset!$D:$D,Dataset!$A:$A,$A3,Dataset!$B:$B,$B3,Dataset!$C:$C,"borrowings_incl_leases"),SUMIFS(Dataset!$D:$D,Dataset!$A:$A,$A3,Dataset!$B:$B,$B3,Dataset!$C:$C,"debt_financial")+SUMIFS(Dataset!$D:$D,Dataset!$A:$A,$A3,Dataset!$B:$B,$B3,Dataset!$C:$C,"lease_liabilities")) -> 31401 | R3: =Q3-P3-SUMIFS(Dataset!$D:$D,Dataset!$A:$A,$A3,Dataset!$B:$B,$B3,Dataset!$C:$C,"liquid_investments") -> 17944 | S3: =D3*IF(C3="GBP",INDEX(FX!$F$2:$F$4,MATCH(B3,FX!$A$2:$A$4,0)),1) -> 51722 | T3: =O3*IF(C3="GBP",INDEX(FX!$F$2:$F$4,MATCH(B3,FX!$A$2:$A$4,0)),1) -> 13805
A4: Novartis | B4: 2025 | C4: USD | D4: =SUMIFS(Dataset!$D:$D,Dataset!$A:$A,$A4,Dataset!$B:$B,$B4,Dataset!$C:$C,"revenue") -> 56674 | E4: =SUMIFS(Dataset!$D:$D,Dataset!$A:$A,$A4,Dataset!$B:$B,$B4,Dataset!$C:$C,"operating_profit") -> 17644 | F4: =E4/D4 -> 0.31132442 | G4: =SUMIFS(Dataset!$D:$D,Dataset!$A:$A,$A4,Dataset!$B:$B,$B4,Dataset!$C:$C,"profit_continuing") -> 13967 | H4: =G4/D4 -> 0.24644458 | I4: =SUMIFS(Dataset!$D:$D,Dataset!$A:$A,$A4,Dataset!$B:$B,$B4,Dataset!$C:$C,"rnd") -> 11200 | J4: =I4/D4 -> 0.19762148 | K4: =SUMIFS(Dataset!$D:$D,Dataset!$A:$A,$A4,Dataset!$B:$B,$B4,Dataset!$C:$C,"cfo") -> 19144 | L4: =SUMIFS(Dataset!$D:$D,Dataset!$A:$A,$A4,Dataset!$B:$B,$B4,Dataset!$C:$C,"capex_ppe") -> 1548 | M4: =SUMIFS(Dataset!$D:$D,Dataset!$A:$A,$A4,Dataset!$B:$B,$B4,Dataset!$C:$C,"capex_intangibles") -> 2352 | N4: =K4-L4 -> 17596 | O4: =K4-L4-M4 -> 15244 | P4: =SUMIFS(Dataset!$D:$D,Dataset!$A:$A,$A4,Dataset!$B:$B,$B4,Dataset!$C:$C,"cash") -> 11435 | Q4: =IF(SUMIFS(Dataset!$D:$D,Dataset!$A:$A,$A4,Dataset!$B:$B,$B4,Dataset!$C:$C,"borrowings_incl_leases")<>0,SUMIFS(Dataset!$D:$D,Dataset!$A:$A,$A4,Dataset!$B:$B,$B4,Dataset!$C:$C,"borrowings_incl_leases"),SUMIFS(Dataset!$D:$D,Dataset!$A:$A,$A4,Dataset!$B:$B,$B4,Dataset!$C:$C,"debt_financial")+SUMIFS(Dataset!$D:$D,Dataset!$A:$A,$A4,Dataset!$B:$B,$B4,Dataset!$C:$C,"lease_liabilities")) -> 35457 | R4: =Q4-P4-SUMIFS(Dataset!$D:$D,Dataset!$A:$A,$A4,Dataset!$B:$B,$B4,Dataset!$C:$C,"liquid_investments") -> 23867 | S4: =D4*IF(C4="GBP",INDEX(FX!$F$2:$F$4,MATCH(B4,FX!$A$2:$A$4,0)),1) -> 56674 | T4: =O4*IF(C4="GBP",INDEX(FX!$F$2:$F$4,MATCH(B4,FX!$A$2:$A$4,0)),1) -> 15244
A5: AstraZeneca | B5: 2023 | C5: USD | D5: =SUMIFS(Dataset!$D:$D,Dataset!$A:$A,$A5,Dataset!$B:$B,$B5,Dataset!$C:$C,"revenue") -> 45811 | E5: =SUMIFS(Dataset!$D:$D,Dataset!$A:$A,$A5,Dataset!$B:$B,$B5,Dataset!$C:$C,"operating_profit") -> 8193 | F5: =E5/D5 -> 0.17884351 | G5: =SUMIFS(Dataset!$D:$D,Dataset!$A:$A,$A5,Dataset!$B:$B,$B5,Dataset!$C:$C,"profit_continuing") -> 5961 | H5: =G5/D5 -> 0.13012159 | I5: =SUMIFS(Dataset!$D:$D,Dataset!$A:$A,$A5,Dataset!$B:$B,$B5,Dataset!$C:$C,"rnd") -> 10935 | J5: =I5/D5 -> 0.23869813 | K5: =SUMIFS(Dataset!$D:$D,Dataset!$A:$A,$A5,Dataset!$B:$B,$B5,Dataset!$C:$C,"cfo") -> 10345 | L5: =SUMIFS(Dataset!$D:$D,Dataset!$A:$A,$A5,Dataset!$B:$B,$B5,Dataset!$C:$C,"capex_ppe") -> 1361 | M5: =SUMIFS(Dataset!$D:$D,Dataset!$A:$A,$A5,Dataset!$B:$B,$B5,Dataset!$C:$C,"capex_intangibles") -> 2417 | N5: =K5-L5 -> 8984 | O5: =K5-L5-M5 -> 6567 | P5: =SUMIFS(Dataset!$D:$D,Dataset!$A:$A,$A5,Dataset!$B:$B,$B5,Dataset!$C:$C,"cash") -> 5840 | Q5: =IF(SUMIFS(Dataset!$D:$D,Dataset!$A:$A,$A5,Dataset!$B:$B,$B5,Dataset!$C:$C,"borrowings_incl_leases")<>0,SUMIFS(Dataset!$D:$D,Dataset!$A:$A,$A5,Dataset!$B:$B,$B5,Dataset!$C:$C,"borrowings_incl_leases"),SUMIFS(Dataset!$D:$D,Dataset!$A:$A,$A5,Dataset!$B:$B,$B5,Dataset!$C:$C,"debt_financial")+SUMIFS(Dataset!$D:$D,Dataset!$A:$A,$A5,Dataset!$B:$B,$B5,Dataset!$C:$C,"lease_liabilities")) -> 28622 | R5: =Q5-P5-SUMIFS(Dataset!$D:$D,Dataset!$A:$A,$A5,Dataset!$B:$B,$B5,Dataset!$C:$C,"liquid_investments") -> 22782 | S5: =D5*IF(C5="GBP",INDEX(FX!$F$2:$F$4,MATCH(B5,FX!$A$2:$A$4,0)),1) -> 45811 | T5: =O5*IF(C5="GBP",INDEX(FX!$F$2:$F$4,MATCH(B5,FX!$A$2:$A$4,0)),1) -> 6567
A6: AstraZeneca | B6: 2024 | C6: USD | D6: =SUMIFS(Dataset!$D:$D,Dataset!$A:$A,$A6,Dataset!$B:$B,$B6,Dataset!$C:$C,"revenue") -> 54073 | E6: =SUMIFS(Dataset!$D:$D,Dataset!$A:$A,$A6,Dataset!$B:$B,$B6,Dataset!$C:$C,"operating_profit") -> 10003 | F6: =E6/D6 -> 0.18499066 | G6: =SUMIFS(Dataset!$D:$D,Dataset!$A:$A,$A6,Dataset!$B:$B,$B6,Dataset!$C:$C,"profit_continuing") -> 7041 | H6: =G6/D6 -> 0.13021286 | I6: =SUMIFS(Dataset!$D:$D,Dataset!$A:$A,$A6,Dataset!$B:$B,$B6,Dataset!$C:$C,"rnd") -> 13583 | J6: =I6/D6 -> 0.25119746 | K6: =SUMIFS(Dataset!$D:$D,Dataset!$A:$A,$A6,Dataset!$B:$B,$B6,Dataset!$C:$C,"cfo") -> 11861 | L6: =SUMIFS(Dataset!$D:$D,Dataset!$A:$A,$A6,Dataset!$B:$B,$B6,Dataset!$C:$C,"capex_ppe") -> 1924 | M6: =SUMIFS(Dataset!$D:$D,Dataset!$A:$A,$A6,Dataset!$B:$B,$B6,Dataset!$C:$C,"capex_intangibles") -> 2662 | N6: =K6-L6 -> 9937 | O6: =K6-L6-M6 -> 7275 | P6: =SUMIFS(Dataset!$D:$D,Dataset!$A:$A,$A6,Dataset!$B:$B,$B6,Dataset!$C:$C,"cash") -> 5488 | Q6: =IF(SUMIFS(Dataset!$D:$D,Dataset!$A:$A,$A6,Dataset!$B:$B,$B6,Dataset!$C:$C,"borrowings_incl_leases")<>0,SUMIFS(Dataset!$D:$D,Dataset!$A:$A,$A6,Dataset!$B:$B,$B6,Dataset!$C:$C,"borrowings_incl_leases"),SUMIFS(Dataset!$D:$D,Dataset!$A:$A,$A6,Dataset!$B:$B,$B6,Dataset!$C:$C,"debt_financial")+SUMIFS(Dataset!$D:$D,Dataset!$A:$A,$A6,Dataset!$B:$B,$B6,Dataset!$C:$C,"lease_liabilities")) -> 30295 | R6: =Q6-P6-SUMIFS(Dataset!$D:$D,Dataset!$A:$A,$A6,Dataset!$B:$B,$B6,Dataset!$C:$C,"liquid_investments") -> 24807 | S6: =D6*IF(C6="GBP",INDEX(FX!$F$2:$F$4,MATCH(B6,FX!$A$2:$A$4,0)),1) -> 54073 | T6: =O6*IF(C6="GBP",INDEX(FX!$F$2:$F$4,MATCH(B6,FX!$A$2:$A$4,0)),1) -> 7275
A7: AstraZeneca | B7: 2025 | C7: USD | D7: =SUMIFS(Dataset!$D:$D,Dataset!$A:$A,$A7,Dataset!$B:$B,$B7,Dataset!$C:$C,"revenue") -> 58739 | E7: =SUMIFS(Dataset!$D:$D,Dataset!$A:$A,$A7,Dataset!$B:$B,$B7,Dataset!$C:$C,"operating_profit") -> 13743 | F7: =E7/D7 -> 0.23396721 | G7: =SUMIFS(Dataset!$D:$D,Dataset!$A:$A,$A7,Dataset!$B:$B,$B7,Dataset!$C:$C,"profit_continuing") -> 10233 | H7: =G7/D7 -> 0.17421134 | I7: =SUMIFS(Dataset!$D:$D,Dataset!$A:$A,$A7,Dataset!$B:$B,$B7,Dataset!$C:$C,"rnd") -> 14232 | J7: =I7/D7 -> 0.24229217 | K7: =SUMIFS(Dataset!$D:$D,Dataset!$A:$A,$A7,Dataset!$B:$B,$B7,Dataset!$C:$C,"cfo") -> 14575 | L7: =SUMIFS(Dataset!$D:$D,Dataset!$A:$A,$A7,Dataset!$B:$B,$B7,Dataset!$C:$C,"capex_ppe") -> 2810 | M7: =SUMIFS(Dataset!$D:$D,Dataset!$A:$A,$A7,Dataset!$B:$B,$B7,Dataset!$C:$C,"capex_intangibles") -> 3095 | N7: =K7-L7 -> 11765 | O7: =K7-L7-M7 -> 8670 | P7: =SUMIFS(Dataset!$D:$D,Dataset!$A:$A,$A7,Dataset!$B:$B,$B7,Dataset!$C:$C,"cash") -> 5711 | Q7: =IF(SUMIFS(Dataset!$D:$D,Dataset!$A:$A,$A7,Dataset!$B:$B,$B7,Dataset!$C:$C,"borrowings_incl_leases")<>0,SUMIFS(Dataset!$D:$D,Dataset!$A:$A,$A7,Dataset!$B:$B,$B7,Dataset!$C:$C,"borrowings_incl_leases"),SUMIFS(Dataset!$D:$D,Dataset!$A:$A,$A7,Dataset!$B:$B,$B7,Dataset!$C:$C,"debt_financial")+SUMIFS(Dataset!$D:$D,Dataset!$A:$A,$A7,Dataset!$B:$B,$B7,Dataset!$C:$C,"lease_liabilities")) -> 29622 | R7: =Q7-P7-SUMIFS(Dataset!$D:$D,Dataset!$A:$A,$A7,Dataset!$B:$B,$B7,Dataset!$C:$C,"liquid_investments") -> 23911 | S7: =D7*IF(C7="GBP",INDEX(FX!$F$2:$F$4,MATCH(B7,FX!$A$2:$A$4,0)),1) -> 58739 | T7: =O7*IF(C7="GBP",INDEX(FX!$F$2:$F$4,MATCH(B7,FX!$A$2:$A$4,0)),1) -> 8670
A8: GSK | B8: 2023 | C8: GBP | D8: =SUMIFS(Dataset!$D:$D,Dataset!$A:$A,$A8,Dataset!$B:$B,$B8,Dataset!$C:$C,"revenue") -> 30328 | E8: =SUMIFS(Dataset!$D:$D,Dataset!$A:$A,$A8,Dataset!$B:$B,$B8,Dataset!$C:$C,"operating_profit") -> 6745 | F8: =E8/D8 -> 0.22240174 | G8: =SUMIFS(Dataset!$D:$D,Dataset!$A:$A,$A8,Dataset!$B:$B,$B8,Dataset!$C:$C,"profit_continuing") -> 5308 | H8: =G8/D8 -> 0.17501978 | I8: =SUMIFS(Dataset!$D:$D,Dataset!$A:$A,$A8,Dataset!$B:$B,$B8,Dataset!$C:$C,"rnd") -> 6223 | J8: =I8/D8 -> 0.20518992 | K8: =SUMIFS(Dataset!$D:$D,Dataset!$A:$A,$A8,Dataset!$B:$B,$B8,Dataset!$C:$C,"cfo") -> 6768 | L8: =SUMIFS(Dataset!$D:$D,Dataset!$A:$A,$A8,Dataset!$B:$B,$B8,Dataset!$C:$C,"capex_ppe") -> 1314 | M8: =SUMIFS(Dataset!$D:$D,Dataset!$A:$A,$A8,Dataset!$B:$B,$B8,Dataset!$C:$C,"capex_intangibles") -> 1030 | N8: =K8-L8 -> 5454 | O8: =K8-L8-M8 -> 4424 | P8: =SUMIFS(Dataset!$D:$D,Dataset!$A:$A,$A8,Dataset!$B:$B,$B8,Dataset!$C:$C,"cash") -> 2936 | Q8: =IF(SUMIFS(Dataset!$D:$D,Dataset!$A:$A,$A8,Dataset!$B:$B,$B8,Dataset!$C:$C,"borrowings_incl_leases")<>0,SUMIFS(Dataset!$D:$D,Dataset!$A:$A,$A8,Dataset!$B:$B,$B8,Dataset!$C:$C,"borrowings_incl_leases"),SUMIFS(Dataset!$D:$D,Dataset!$A:$A,$A8,Dataset!$B:$B,$B8,Dataset!$C:$C,"debt_financial")+SUMIFS(Dataset!$D:$D,Dataset!$A:$A,$A8,Dataset!$B:$B,$B8,Dataset!$C:$C,"lease_liabilities")) -> 18018 | R8: =Q8-P8-SUMIFS(Dataset!$D:$D,Dataset!$A:$A,$A8,Dataset!$B:$B,$B8,Dataset!$C:$C,"liquid_investments") -> 15082 | S8: =D8*IF(C8="GBP",INDEX(FX!$F$2:$F$4,MATCH(B8,FX!$A$2:$A$4,0)),1) -> 37702.028 | T8: =O8*IF(C8="GBP",INDEX(FX!$F$2:$F$4,MATCH(B8,FX!$A$2:$A$4,0)),1) -> 5499.6627
A9: GSK | B9: 2024 | C9: GBP | D9: =SUMIFS(Dataset!$D:$D,Dataset!$A:$A,$A9,Dataset!$B:$B,$B9,Dataset!$C:$C,"revenue") -> 31376 | E9: =SUMIFS(Dataset!$D:$D,Dataset!$A:$A,$A9,Dataset!$B:$B,$B9,Dataset!$C:$C,"operating_profit") -> 4021 | F9: =E9/D9 -> 0.12815528 | G9: =SUMIFS(Dataset!$D:$D,Dataset!$A:$A,$A9,Dataset!$B:$B,$B9,Dataset!$C:$C,"profit_continuing") -> 2951 | H9: =G9/D9 -> 0.094052779 | I9: =SUMIFS(Dataset!$D:$D,Dataset!$A:$A,$A9,Dataset!$B:$B,$B9,Dataset!$C:$C,"rnd") -> 6401 | J9: =I9/D9 -> 0.20400943 | K9: =SUMIFS(Dataset!$D:$D,Dataset!$A:$A,$A9,Dataset!$B:$B,$B9,Dataset!$C:$C,"cfo") -> 6554 | L9: =SUMIFS(Dataset!$D:$D,Dataset!$A:$A,$A9,Dataset!$B:$B,$B9,Dataset!$C:$C,"capex_ppe") -> 1399 | M9: =SUMIFS(Dataset!$D:$D,Dataset!$A:$A,$A9,Dataset!$B:$B,$B9,Dataset!$C:$C,"capex_intangibles") -> 1583 | N9: =K9-L9 -> 5155 | O9: =K9-L9-M9 -> 3572 | P9: =SUMIFS(Dataset!$D:$D,Dataset!$A:$A,$A9,Dataset!$B:$B,$B9,Dataset!$C:$C,"cash") -> 3870 | Q9: =IF(SUMIFS(Dataset!$D:$D,Dataset!$A:$A,$A9,Dataset!$B:$B,$B9,Dataset!$C:$C,"borrowings_incl_leases")<>0,SUMIFS(Dataset!$D:$D,Dataset!$A:$A,$A9,Dataset!$B:$B,$B9,Dataset!$C:$C,"borrowings_incl_leases"),SUMIFS(Dataset!$D:$D,Dataset!$A:$A,$A9,Dataset!$B:$B,$B9,Dataset!$C:$C,"debt_financial")+SUMIFS(Dataset!$D:$D,Dataset!$A:$A,$A9,Dataset!$B:$B,$B9,Dataset!$C:$C,"lease_liabilities")) -> 16986 | R9: =Q9-P9-SUMIFS(Dataset!$D:$D,Dataset!$A:$A,$A9,Dataset!$B:$B,$B9,Dataset!$C:$C,"liquid_investments") -> 13116 | S9: =D9*IF(C9="GBP",INDEX(FX!$F$2:$F$4,MATCH(B9,FX!$A$2:$A$4,0)),1) -> 40113.517 | T9: =O9*IF(C9="GBP",INDEX(FX!$F$2:$F$4,MATCH(B9,FX!$A$2:$A$4,0)),1) -> 4566.7224
A10: GSK | B10: 2025 | C10: GBP | D10: =SUMIFS(Dataset!$D:$D,Dataset!$A:$A,$A10,Dataset!$B:$B,$B10,Dataset!$C:$C,"revenue") -> 32667 | E10: =SUMIFS(Dataset!$D:$D,Dataset!$A:$A,$A10,Dataset!$B:$B,$B10,Dataset!$C:$C,"operating_profit") -> 7932 | F10: =E10/D10 -> 0.24281385 | G10: =SUMIFS(Dataset!$D:$D,Dataset!$A:$A,$A10,Dataset!$B:$B,$B10,Dataset!$C:$C,"profit_continuing") -> 6289 | H10: =G10/D10 -> 0.19251844 | I10: =SUMIFS(Dataset!$D:$D,Dataset!$A:$A,$A10,Dataset!$B:$B,$B10,Dataset!$C:$C,"rnd") -> 7525 | J10: =I10/D10 -> 0.23035479 | K10: =SUMIFS(Dataset!$D:$D,Dataset!$A:$A,$A10,Dataset!$B:$B,$B10,Dataset!$C:$C,"cfo") -> 7741 | L10: =SUMIFS(Dataset!$D:$D,Dataset!$A:$A,$A10,Dataset!$B:$B,$B10,Dataset!$C:$C,"capex_ppe") -> 1348 | M10: =SUMIFS(Dataset!$D:$D,Dataset!$A:$A,$A10,Dataset!$B:$B,$B10,Dataset!$C:$C,"capex_intangibles") -> 1637 | N10: =K10-L10 -> 6393 | O10: =K10-L10-M10 -> 4756 | P10: =SUMIFS(Dataset!$D:$D,Dataset!$A:$A,$A10,Dataset!$B:$B,$B10,Dataset!$C:$C,"cash") -> 3397 | Q10: =IF(SUMIFS(Dataset!$D:$D,Dataset!$A:$A,$A10,Dataset!$B:$B,$B10,Dataset!$C:$C,"borrowings_incl_leases")<>0,SUMIFS(Dataset!$D:$D,Dataset!$A:$A,$A10,Dataset!$B:$B,$B10,Dataset!$C:$C,"borrowings_incl_leases"),SUMIFS(Dataset!$D:$D,Dataset!$A:$A,$A10,Dataset!$B:$B,$B10,Dataset!$C:$C,"debt_financial")+SUMIFS(Dataset!$D:$D,Dataset!$A:$A,$A10,Dataset!$B:$B,$B10,Dataset!$C:$C,"lease_liabilities")) -> 17720 | R10: =Q10-P10-SUMIFS(Dataset!$D:$D,Dataset!$A:$A,$A10,Dataset!$B:$B,$B10,Dataset!$C:$C,"liquid_investments") -> 14323 | S10: =D10*IF(C10="GBP",INDEX(FX!$F$2:$F$4,MATCH(B10,FX!$A$2:$A$4,0)),1) -> 43082.972 | T10: =O10*IF(C10="GBP",INDEX(FX!$F$2:$F$4,MATCH(B10,FX!$A$2:$A$4,0)),1) -> 6272.465

Sheet DCF
A1: AstraZeneca DCF (USD millions, valuation date 31 Dec 2025)
A2: Blue cells are inputs. Everything else is a formula. Scenario assumptions are illustrative, not forecasts.
A4: Base year (fiscal) | B4: 2025
A5: Base revenue | B5: =SUMIFS(Dataset!$D:$D,Dataset!$A:$A,"AstraZeneca",Dataset!$B:$B,2025,Dataset!$C:$C,"revenue") -> 58739
A6: Base operating margin | B6: =SUMIFS(Dataset!$D:$D,Dataset!$A:$A,"AstraZeneca",Dataset!$B:$B,2025,Dataset!$C:$C,"operating_profit")/B5 -> 0.23396721
A7: Tax rate on operating profit | B7: 0.18
A8: D&A, % of revenue | B8: 0.09
A9: Capex (PP&E + intangibles), % of revenue | B9: 0.1
A10: Investment in working capital, % of revenue | B10: 0.01
A11: Operating margin in final forecast year | B11: 0.25
A12: WACC | B12: 0.075
A13: Terminal growth | B13: 0.02
A16: Forecast year (t) | B16: 1 | C16: 2 | D16: 3 | E16: 4 | F16: 5
A17: Fiscal year | B17: =$B$4+B16 -> 2026 | C17: =$B$4+C16 -> 2027 | D17: =$B$4+D16 -> 2028 | E17: =$B$4+E16 -> 2029 | F17: =$B$4+F16 -> 2030
A18: Revenue growth | B18: 0.07 | C18: 0.06 | D18: 0.05 | E18: 0.04 | F18: 0.035
A19: Revenue | B19: =B5*(1+B18) -> 62850.73 | C19: =B19*(1+C18) -> 66621.774 | D19: =C19*(1+D18) -> 69952.862 | E19: =D19*(1+E18) -> 72750.977 | F19: =E19*(1+F18) -> 75297.261
A20: Operating margin | B20: =$B$6+($B$11-$B$6)*B16/5 -> 0.23717377 | C20: =$B$6+($B$11-$B$6)*C16/5 -> 0.24038033 | D20: =$B$6+($B$11-$B$6)*D16/5 -> 0.24358688 | E20: =$B$6+($B$11-$B$6)*E16/5 -> 0.24679344 | F20: =$B$6+($B$11-$B$6)*F16/5 -> 0.25
A21: Operating profit (EBIT) | B21: =B19*B20 -> 14906.544 | C21: =C19*C20 -> 16014.564 | D21: =D19*D20 -> 17039.6 | E21: =E19*E20 -> 17954.464 | F21: =F19*F20 -> 18824.315
A22: NOPAT (EBIT x (1 - tax)) | B22: =B21*(1-$B$7) -> 12223.366 | C22: =C21*(1-$B$7) -> 13131.942 | D22: =D21*(1-$B$7) -> 13972.472 | E22: =E21*(1-$B$7) -> 14722.661 | F22: =F21*(1-$B$7) -> 15435.939
A23: Plus: D&A | B23: =B19*$B$8 -> 5656.5657 | C23: =C19*$B$8 -> 5995.9596 | D23: =D19*$B$8 -> 6295.7576 | E23: =E19*$B$8 -> 6547.5879 | F23: =F19*$B$8 -> 6776.7535
A24: Less: capex (PP&E + intangibles) | B24: =B19*$B$9 -> 6285.073 | C24: =C19*$B$9 -> 6662.1774 | D24: =D19*$B$9 -> 6995.2862 | E24: =E19*$B$9 -> 7275.0977 | F24: =F19*$B$9 -> 7529.7261
A25: Less: investment in working capital | B25: =B19*$B$10 -> 628.5073 | C25: =C19*$B$10 -> 666.21774 | D25: =D19*$B$10 -> 699.52862 | E25: =E19*$B$10 -> 727.50977 | F25: =F19*$B$10 -> 752.97261
A26: Free cash flow to the firm | B26: =B22+B23-B24-B25 -> 10966.352 | C26: =C22+C23-C24-C25 -> 11799.507 | D26: =D22+D23-D24-D25 -> 12573.415 | E26: =E22+E23-E24-E25 -> 13267.641 | F26: =F22+F23-F24-F25 -> 13929.993
A27: Discount factor | B27: =1/(1+$B$12)^B16 -> 0.93023256 | C27: =1/(1+$B$12)^C16 -> 0.86533261 | D27: =1/(1+$B$12)^D16 -> 0.80496057 | E27: =1/(1+$B$12)^E16 -> 0.74880053 | F27: =1/(1+$B$12)^F16 -> 0.69655863
A28: Present value of FCFF | B28: =B26*B27 -> 10201.258 | C28: =C26*C27 -> 10210.498 | D28: =D26*D27 -> 10121.103 | E28: =E26*E27 -> 9934.8166 | F28: =F26*F27 -> 9703.0571
A30: Sum of present values of FCFF | B30: =SUM(B28:F28) -> 50170.732
A31: Terminal value at end of year 5 (Gordon growth) | B31: =F26*(1+B13)/(B12-B13) -> 258338.06
A32: Present value of terminal value | B32: =B31*F27 -> 179947.6
A33: Enterprise value | B33: =B30+B32 -> 230118.34
A34: Terminal value as share of enterprise value | B34: =B32/B33 -> 0.78197855
A36: Enterprise-to-equity bridge (31 Dec 2025 balance sheet)
A37: Debt including lease liabilities | B37: =SUMIFS(Dataset!$D:$D,Dataset!$A:$A,"AstraZeneca",Dataset!$B:$B,2025,Dataset!$C:$C,"borrowings_incl_leases") -> 29622
A38: Cash and cash equivalents | B38: =SUMIFS(Dataset!$D:$D,Dataset!$A:$A,"AstraZeneca",Dataset!$B:$B,2025,Dataset!$C:$C,"cash") -> 5711
A39: Equity-accounted investments (book value) | B39: =SUMIFS(Dataset!$D:$D,Dataset!$A:$A,"AstraZeneca",Dataset!$B:$B,2025,Dataset!$C:$C,"equity_method_investments") -> 302
A40: Pension deficit (retirement benefit obligations, pre-tax) | B40: =SUMIFS(Dataset!$D:$D,Dataset!$A:$A,"AstraZeneca",Dataset!$B:$B,2025,Dataset!$C:$C,"pension_liability") -> 1105
A41: Non-controlling interests (book value) | B41: =SUMIFS(Dataset!$D:$D,Dataset!$A:$A,"AstraZeneca",Dataset!$B:$B,2025,Dataset!$C:$C,"nci_book") -> 52
A42: Equity value | B42: =B33-B37+B38+B39-B40-B41 -> 205352.34
A43: Ordinary shares outstanding (millions) | B43: =SUMIFS(Dataset!$D:$D,Dataset!$A:$A,"AstraZeneca",Dataset!$B:$B,2025,Dataset!$C:$C,"shares_outstanding_m") -> 1550.9079
A44: Value per ordinary share (USD) | B44: =B42/B43 -> 132.40782
A46: Not included in the bridge: contingent consideration, litigation and other provisions, deferred tax, other investments, dividends declared. The bridge is partial.

Sheet Sensitivity
A1: Value per ordinary share (USD) across WACC (rows) and terminal growth (columns). Same FCFF as the DCF sheet.
A4: WACC \ g | B4: 0.01 | C4: 0.015 | D4: 0.02 | E4: 0.025 | F4: 0.03
A5: 0.06 | B5: =IF($A5<=B$4,NA(),(SUMPRODUCT(DCF!$B$26:$F$26/(1+$A5)^DCF!$B$16:$F$16)+DCF!$F$26*(1+B$4)/($A5-B$4)/(1+$A5)^5-DCF!$B$37+DCF!$B$38+DCF!$B$39-DCF!$B$40-DCF!$B$41)/DCF!$B$43) -> 153.34529 | C5: =IF($A5<=C$4,NA(),(SUMPRODUCT(DCF!$B$26:$F$26/(1+$A5)^DCF!$B$16:$F$16)+DCF!$F$26*(1+C$4)/($A5-C$4)/(1+$A5)^5-DCF!$B$37+DCF!$B$38+DCF!$B$39-DCF!$B$40-DCF!$B$41)/DCF!$B$43) -> 169.15518 | D5: =IF($A5<=D$4,NA(),(SUMPRODUCT(DCF!$B$26:$F$26/(1+$A5)^DCF!$B$16:$F$16)+DCF!$F$26*(1+D$4)/($A5-D$4)/(1+$A5)^5-DCF!$B$37+DCF!$B$38+DCF!$B$39-DCF!$B$40-DCF!$B$41)/DCF!$B$43) -> 188.91754 | E5: =IF($A5<=E$4,NA(),(SUMPRODUCT(DCF!$B$26:$F$26/(1+$A5)^DCF!$B$16:$F$16)+DCF!$F$26*(1+E$4)/($A5-E$4)/(1+$A5)^5-DCF!$B$37+DCF!$B$38+DCF!$B$39-DCF!$B$40-DCF!$B$41)/DCF!$B$43) -> 214.3263 | F5: =IF($A5<=F$4,NA(),(SUMPRODUCT(DCF!$B$26:$F$26/(1+$A5)^DCF!$B$16:$F$16)+DCF!$F$26*(1+F$4)/($A5-F$4)/(1+$A5)^5-DCF!$B$37+DCF!$B$38+DCF!$B$39-DCF!$B$40-DCF!$B$41)/DCF!$B$43) -> 248.20464
A6: 0.065 | B6: =IF($A6<=B$4,NA(),(SUMPRODUCT(DCF!$B$26:$F$26/(1+$A6)^DCF!$B$16:$F$16)+DCF!$F$26*(1+B$4)/($A6-B$4)/(1+$A6)^5-DCF!$B$37+DCF!$B$38+DCF!$B$39-DCF!$B$40-DCF!$B$41)/DCF!$B$43) -> 137.68127 | C6: =IF($A6<=C$4,NA(),(SUMPRODUCT(DCF!$B$26:$F$26/(1+$A6)^DCF!$B$16:$F$16)+DCF!$F$26*(1+C$4)/($A6-C$4)/(1+$A6)^5-DCF!$B$37+DCF!$B$38+DCF!$B$39-DCF!$B$40-DCF!$B$41)/DCF!$B$43) -> 150.37542 | D6: =IF($A6<=D$4,NA(),(SUMPRODUCT(DCF!$B$26:$F$26/(1+$A6)^DCF!$B$16:$F$16)+DCF!$F$26*(1+D$4)/($A6-D$4)/(1+$A6)^5-DCF!$B$37+DCF!$B$38+DCF!$B$39-DCF!$B$40-DCF!$B$41)/DCF!$B$43) -> 165.8905 | E6: =IF($A6<=E$4,NA(),(SUMPRODUCT(DCF!$B$26:$F$26/(1+$A6)^DCF!$B$16:$F$16)+DCF!$F$26*(1+E$4)/($A6-E$4)/(1+$A6)^5-DCF!$B$37+DCF!$B$38+DCF!$B$39-DCF!$B$40-DCF!$B$41)/DCF!$B$43) -> 185.28434 | F6: =IF($A6<=F$4,NA(),(SUMPRODUCT(DCF!$B$26:$F$26/(1+$A6)^DCF!$B$16:$F$16)+DCF!$F$26*(1+F$4)/($A6-F$4)/(1+$A6)^5-DCF!$B$37+DCF!$B$38+DCF!$B$39-DCF!$B$40-DCF!$B$41)/DCF!$B$43) -> 210.21929
A7: 0.07 | B7: =IF($A7<=B$4,NA(),(SUMPRODUCT(DCF!$B$26:$F$26/(1+$A7)^DCF!$B$16:$F$16)+DCF!$F$26*(1+B$4)/($A7-B$4)/(1+$A7)^5-DCF!$B$37+DCF!$B$38+DCF!$B$39-DCF!$B$40-DCF!$B$41)/DCF!$B$43) -> 124.63235 | C7: =IF($A7<=C$4,NA(),(SUMPRODUCT(DCF!$B$26:$F$26/(1+$A7)^DCF!$B$16:$F$16)+DCF!$F$26*(1+C$4)/($A7-C$4)/(1+$A7)^5-DCF!$B$37+DCF!$B$38+DCF!$B$39-DCF!$B$40-DCF!$B$41)/DCF!$B$43) -> 135.01446 | D7: =IF($A7<=D$4,NA(),(SUMPRODUCT(DCF!$B$26:$F$26/(1+$A7)^DCF!$B$16:$F$16)+DCF!$F$26*(1+D$4)/($A7-D$4)/(1+$A7)^5-DCF!$B$37+DCF!$B$38+DCF!$B$39-DCF!$B$40-DCF!$B$41)/DCF!$B$43) -> 147.473 | E7: =IF($A7<=E$4,NA(),(SUMPRODUCT(DCF!$B$26:$F$26/(1+$A7)^DCF!$B$16:$F$16)+DCF!$F$26*(1+E$4)/($A7-E$4)/(1+$A7)^5-DCF!$B$37+DCF!$B$38+DCF!$B$39-DCF!$B$40-DCF!$B$41)/DCF!$B$43) -> 162.7001 | F7: =IF($A7<=F$4,NA(),(SUMPRODUCT(DCF!$B$26:$F$26/(1+$A7)^DCF!$B$16:$F$16)+DCF!$F$26*(1+F$4)/($A7-F$4)/(1+$A7)^5-DCF!$B$37+DCF!$B$38+DCF!$B$39-DCF!$B$40-DCF!$B$41)/DCF!$B$43) -> 181.73398
A8: 0.075 | B8: =IF($A8<=B$4,NA(),(SUMPRODUCT(DCF!$B$26:$F$26/(1+$A8)^DCF!$B$16:$F$16)+DCF!$F$26*(1+B$4)/($A8-B$4)/(1+$A8)^5-DCF!$B$37+DCF!$B$38+DCF!$B$39-DCF!$B$40-DCF!$B$41)/DCF!$B$43) -> 113.59495 | C8: =IF($A8<=C$4,NA(),(SUMPRODUCT(DCF!$B$26:$F$26/(1+$A8)^DCF!$B$16:$F$16)+DCF!$F$26*(1+C$4)/($A8-C$4)/(1+$A8)^5-DCF!$B$37+DCF!$B$38+DCF!$B$39-DCF!$B$40-DCF!$B$41)/DCF!$B$43) -> 122.21752 | D8: =IF($A8<=D$4,NA(),(SUMPRODUCT(DCF!$B$26:$F$26/(1+$A8)^DCF!$B$16:$F$16)+DCF!$F$26*(1+D$4)/($A8-D$4)/(1+$A8)^5-DCF!$B$37+DCF!$B$38+DCF!$B$39-DCF!$B$40-DCF!$B$41)/DCF!$B$43) -> 132.40782 | E8: =IF($A8<=E$4,NA(),(SUMPRODUCT(DCF!$B$26:$F$26/(1+$A8)^DCF!$B$16:$F$16)+DCF!$F$26*(1+E$4)/($A8-E$4)/(1+$A8)^5-DCF!$B$37+DCF!$B$38+DCF!$B$39-DCF!$B$40-DCF!$B$41)/DCF!$B$43) -> 144.63618 | F8: =IF($A8<=F$4,NA(),(SUMPRODUCT(DCF!$B$26:$F$26/(1+$A8)^DCF!$B$16:$F$16)+DCF!$F$26*(1+F$4)/($A8-F$4)/(1+$A8)^5-DCF!$B$37+DCF!$B$38+DCF!$B$39-DCF!$B$40-DCF!$B$41)/DCF!$B$43) -> 159.58196
A9: 0.08 | B9: =IF($A9<=B$4,NA(),(SUMPRODUCT(DCF!$B$26:$F$26/(1+$A9)^DCF!$B$16:$F$16)+DCF!$F$26*(1+B$4)/($A9-B$4)/(1+$A9)^5-DCF!$B$37+DCF!$B$38+DCF!$B$39-DCF!$B$40-DCF!$B$41)/DCF!$B$43) -> 104.13795 | C9: =IF($A9<=C$4,NA(),(SUMPRODUCT(DCF!$B$26:$F$26/(1+$A9)^DCF!$B$16:$F$16)+DCF!$F$26*(1+C$4)/($A9-C$4)/(1+$A9)^5-DCF!$B$37+DCF!$B$38+DCF!$B$39-DCF!$B$40-DCF!$B$41)/DCF!$B$43) -> 111.3928 | D9: =IF($A9<=D$4,NA(),(SUMPRODUCT(DCF!$B$26:$F$26/(1+$A9)^DCF!$B$16:$F$16)+DCF!$F$26*(1+D$4)/($A9-D$4)/(1+$A9)^5-DCF!$B$37+DCF!$B$38+DCF!$B$39-DCF!$B$40-DCF!$B$41)/DCF!$B$43) -> 119.85679 | E9: =IF($A9<=E$4,NA(),(SUMPRODUCT(DCF!$B$26:$F$26/(1+$A9)^DCF!$B$16:$F$16)+DCF!$F$26*(1+E$4)/($A9-E$4)/(1+$A9)^5-DCF!$B$37+DCF!$B$38+DCF!$B$39-DCF!$B$40-DCF!$B$41)/DCF!$B$43) -> 129.85969 | F9: =IF($A9<=F$4,NA(),(SUMPRODUCT(DCF!$B$26:$F$26/(1+$A9)^DCF!$B$16:$F$16)+DCF!$F$26*(1+F$4)/($A9-F$4)/(1+$A9)^5-DCF!$B$37+DCF!$B$38+DCF!$B$39-DCF!$B$40-DCF!$B$41)/DCF!$B$43) -> 141.86317
A10: 0.085 | B10: =IF($A10<=B$4,NA(),(SUMPRODUCT(DCF!$B$26:$F$26/(1+$A10)^DCF!$B$16:$F$16)+DCF!$F$26*(1+B$4)/($A10-B$4)/(1+$A10)^5-DCF!$B$37+DCF!$B$38+DCF!$B$39-DCF!$B$40-DCF!$B$41)/DCF!$B$43) -> 95.94518 | C10: =IF($A10<=C$4,NA(),(SUMPRODUCT(DCF!$B$26:$F$26/(1+$A10)^DCF!$B$16:$F$16)+DCF!$F$26*(1+C$4)/($A10-C$4)/(1+$A10)^5-DCF!$B$37+DCF!$B$38+DCF!$B$39-DCF!$B$40-DCF!$B$41)/DCF!$B$43) -> 102.11762 | D10: =IF($A10<=D$4,NA(),(SUMPRODUCT(DCF!$B$26:$F$26/(1+$A10)^DCF!$B$16:$F$16)+DCF!$F$26*(1+D$4)/($A10-D$4)/(1+$A10)^5-DCF!$B$37+DCF!$B$38+DCF!$B$39-DCF!$B$40-DCF!$B$41)/DCF!$B$43) -> 109.23966 | E10: =IF($A10<=E$4,NA(),(SUMPRODUCT(DCF!$B$26:$F$26/(1+$A10)^DCF!$B$16:$F$16)+DCF!$F$26*(1+E$4)/($A10-E$4)/(1+$A10)^5-DCF!$B$37+DCF!$B$38+DCF!$B$39-DCF!$B$40-DCF!$B$41)/DCF!$B$43) -> 117.54871 | F10: =IF($A10<=F$4,NA(),(SUMPRODUCT(DCF!$B$26:$F$26/(1+$A10)^DCF!$B$16:$F$16)+DCF!$F$26*(1+F$4)/($A10-F$4)/(1+$A10)^5-DCF!$B$37+DCF!$B$38+DCF!$B$39-DCF!$B$40-DCF!$B$41)/DCF!$B$43) -> 127.36849
A11: 0.09 | B11: =IF($A11<=B$4,NA(),(SUMPRODUCT(DCF!$B$26:$F$26/(1+$A11)^DCF!$B$16:$F$16)+DCF!$F$26*(1+B$4)/($A11-B$4)/(1+$A11)^5-DCF!$B$37+DCF!$B$38+DCF!$B$39-DCF!$B$40-DCF!$B$41)/DCF!$B$43) -> 88.77953 | C11: =IF($A11<=C$4,NA(),(SUMPRODUCT(DCF!$B$26:$F$26/(1+$A11)^DCF!$B$16:$F$16)+DCF!$F$26*(1+C$4)/($A11-C$4)/(1+$A11)^5-DCF!$B$37+DCF!$B$38+DCF!$B$39-DCF!$B$40-DCF!$B$41)/DCF!$B$43) -> 94.081993 | D11: =IF($A11<=D$4,NA(),(SUMPRODUCT(DCF!$B$26:$F$26/(1+$A11)^DCF!$B$16:$F$16)+DCF!$F$26*(1+D$4)/($A11-D$4)/(1+$A11)^5-DCF!$B$37+DCF!$B$38+DCF!$B$39-DCF!$B$40-DCF!$B$41)/DCF!$B$43) -> 100.14195 | E11: =IF($A11<=E$4,NA(),(SUMPRODUCT(DCF!$B$26:$F$26/(1+$A11)^DCF!$B$16:$F$16)+DCF!$F$26*(1+E$4)/($A11-E$4)/(1+$A11)^5-DCF!$B$37+DCF!$B$38+DCF!$B$39-DCF!$B$40-DCF!$B$41)/DCF!$B$43) -> 107.13421 | F11: =IF($A11<=F$4,NA(),(SUMPRODUCT(DCF!$B$26:$F$26/(1+$A11)^DCF!$B$16:$F$16)+DCF!$F$26*(1+F$4)/($A11-F$4)/(1+$A11)^5-DCF!$B$37+DCF!$B$38+DCF!$B$39-DCF!$B$40-DCF!$B$41)/DCF!$B$43) -> 115.29185

Sheet Checks
A1: Check | B1: Result | C1: Detail
A2: Bridge identity: equity = EV - debt + cash + investments - pension - NCI | B2: =ABS(DCF!B42-(DCF!B33-DCF!B37+DCF!B38+DCF!B39-DCF!B40-DCF!B41))<0.001 -> TRUE | C2: DCF!B42
A3: WACC exceeds terminal growth | B3: =DCF!B12>DCF!B13 -> TRUE | C3: DCF!B12 vs DCF!B13
A4: Discount factors fall each year | B4: =AND(DCF!C27<DCF!B27,DCF!D27<DCF!C27,DCF!E27<DCF!D27,DCF!F27<DCF!E27) -> TRUE | C4: DCF!B27:F27
A5: Terminal value share of EV is between 0 and 100% | B5: =AND(DCF!B34>0,DCF!B34<1) -> TRUE | C5: DCF!B34
A6: Sensitivity centre (7.5% WACC, 2.0% growth) equals DCF value per share | B6: =ABS(Sensitivity!D8-DCF!B44)<0.001 -> TRUE | C6: Sensitivity!D8
A7: Value per share matches the web model's reference value for the same inputs (within 0.01%) | B7: =ABS(DCF!B44-132.407819317508)/132.407819317508<0.0001 -> TRUE | C7: reference 132.4078 from tests/pharma
A8: Enterprise value matches the web model's reference value (within 0.01%) | B8: =ABS(DCF!B33-230118.336576307)/230118.336576307<0.0001 -> TRUE | C8: reference 230118.34
A9: Novartis 2025 net debt incl. leases less reported net debt (21,947) equals lease liabilities | B9: =ABS((Comparables!R4-21947)-SUMIFS(Dataset!$D:$D,Dataset!$A:$A,"Novartis",Dataset!$B:$B,2025,Dataset!$C:$C,"lease_liabilities"))<0.5 -> TRUE | C9: Comparables row 4 (Novartis 2025)
